Workbook

Sheet Raw_Data
A1: Order ID | B1: Order Date | C1: Customer ID | D1: Type | E1: SKU | F1: Category | G1: Product Name | H1: Unit Price | I1: Qty | J1: Total | K1: Discount Code | L1: Disc % | M1: Payment | N1: Source | O1: City | P1: State | Q1: Warehouse | R1: Del Date | S1: Status | T1: Return? | U1: Reason | V1: Ret Rec | W1: Refund | AB1: Duplicate_Count
A2: UT-100001 | B2: 45566 | C2: CUST_10001 | D2: New | E2: TOP-CAS-M | F2: Tops | G2: Classic Cotton Tee | H2: 1299 | I2: 2 | J2: 2598 | L2: 0 | M2: UPI | N2: Website | O2: Mumbai | P2: Maharashtra | Q2: Mumbai | R2: 45570 | S2: Delivered | T2: No | W2: Not Applicable | AA2: =COUNTBLANK(U2:U347) -> 166 | AB2: =COUNTIF(A$2:A$347,A2) -> 1 | AC2: =LEN(S2)-LEN(TRIM(S2)) -> 0 | AD2: =LEN(E2)-LEN(SUBSTITUTE(E2,"-","")) -> 2 | AE2: =IF(I2>10,"FLAG","OK") -> OK | AF2: =IF(OR(H2<=0,H2>10000),"FLAG","OK") -> OK | AG2: =IF(OR(L2<0,L2>100),"FLAG","OK") -> OK | AH2: =ROUND((H2*I2)*(1-L2/100),0) -> 2598 | AI2: =IF(AG2=J2,"OK","ERROR") -> ERROR | AJ2: =IF(R2<B2,"ERROR","OK") -> OK | AK2: =IF(AND(S2="Cancelled",R2<>""),"ERROR","OK") -> OK | AL2: =IF(AND(T2="Yes",U2=""),"ERROR","OK") -> OK | AM2: =IF(V2<R2,"ERROR","OK") -> ERROR | AN2: =IF(AND(I2>0,MOD(I2,1)=0),"OK","ERROR") -> OK | AO2: =IF(OR(B2="",B2<DATE(2024,10,1),B2>DATE(2024,12,31)),"ERROR","OK") -> OK | AP2: =IF(OR(B2<DATE(2024,10,1),B2>DATE(2024,12,31)),"ERROR","OK") -> OK | AQ2: =IF(OR(S2="Delivered",S2="Cancelled",S2="RTO",S2="In Transit"),"OK","ERROR") -> OK
A3: UT-100002 | B3: 45566 | C3: CUST_10002 | D3: Returning | E3: DRS-FRM-S | F3: Dresses | G3: Floral Midi Dress | H3: 2499 | I3: 1 | J3: 2499 | K3: DIWALI20 | L3: 20 | M3: Credit Card | N3: Mobile App | O3: Delhi | P3: Delhi | Q3: Delhi | R3: 45569 | S3: Delivered | T3: Yes | U3: Size Issue | V3: 45580 | W3: Processed | AA3: =COUNTBLANK(R2:R347) -> 18 | AB3: =COUNTIF(A$2:A$347,A3) -> 1 | AC3: =LEN(S3)-LEN(TRIM(S3)) -> 0 | AD3: =LEN(E3)-LEN(SUBSTITUTE(E3,"-","")) -> 2 | AE3: =IF(I3>10,"FLAG","OK") -> OK | AF3: =IF(OR(H3<=0,H3>10000),"FLAG","OK") -> OK | AG3: =IF(OR(L3<0,L3>100),"FLAG","OK") -> OK | AI3: =IF(AG3=J3,"OK","ERROR") -> ERROR | AJ3: =IF(R3<B3,"ERROR","OK") -> OK | AK3: =IF(AND(S3="Cancelled",R3<>""),"ERROR","OK") -> OK | AL3: =IF(AND(T3="Yes",U3=""),"ERROR","OK") -> OK | AM3: =IF(V3<R3,"ERROR","OK") -> OK | AN3: =IF(AND(I3>0,MOD(I3,1)=0),"OK","ERROR") -> OK | AO3: =IF(OR(B3="",B3<DATE(2024,10,1),B3>DATE(2024,12,31)),"ERROR","OK") -> OK | AP3: =IF(OR(B3<DATE(2024,10,1),B3>DATE(2024,12,31)),"ERROR","OK") -> OK | AQ3: =IF(OR(S3="Delivered",S3="Cancelled",S3="RTO",S3="In Transit"),"OK","ERROR") -> OK
A4: UT-100003 | B4: 45301 | C4: CUST_10003 | D4: new | E4: BOT-JNS-L | F4: Bottoms | G4: Slim Fit Jeans | H4: 1899 | I4: 1 | J4: 1899 | L4: 0 | M4: COD | N4: Website | O4: Bangalore | P4: Karnataka | Q4: Bangalore | R4: 45571 | S4: Delivered | T4: No | W4: Not Applicable | AA4: =COUNTBLANK(K2:K347) -> 206 | AB4: =COUNTIF(A$2:A$347,A4) -> 1 | AC4: =LEN(S4)-LEN(TRIM(S4)) -> 0 | AD4: =LEN(E4)-LEN(SUBSTITUTE(E4,"-","")) -> 2 | AE4: =IF(I4>10,"FLAG","OK") -> OK | AF4: =IF(OR(H4<=0,H4>10000),"FLAG","OK") -> OK | AG4: =IF(OR(L4<0,L4>100),"FLAG","OK") -> OK | AI4: =IF(AG4=J4,"OK","ERROR") -> ERROR | AJ4: =IF(R4<B4,"ERROR","OK") -> OK | AK4: =IF(AND(S4="Cancelled",R4<>""),"ERROR","OK") -> OK | AL4: =IF(AND(T4="Yes",U4=""),"ERROR","OK") -> OK | AM4: =IF(V4<R4,"ERROR","OK") -> ERROR | AN4: =IF(AND(I4>0,MOD(I4,1)=0),"OK","ERROR") -> OK | AO4: =IF(OR(B4="",B4<DATE(2024,10,1),B4>DATE(2024,12,31)),"ERROR","OK") -> ERROR | AP4: =IF(OR(B4<DATE(2024,10,1),B4>DATE(2024,12,31)),"ERROR","OK") -> ERROR | AQ4: =IF(OR(S4="Delivered",S4="Cancelled",S4="RTO",S4="In Transit"),"OK","ERROR") -> OK
A5: UT-100004 | B5: 45566 | C5: CUST_10004 | D5: New | E5: OUT-JKT-XL | F5: Outerwear | G5: Denim Jacket | H5: 3499 | I5: 1 | J5: 3499 | K5: FIRST15 | L5: 15 | M5: Debit Card | N5: Instagram Shop | O5: Chennai | P5: Tamil Nadu | Q5: Mumbai | R5: 45573 | S5: Delivered | T5: Yes | U5: Quality Defect | V5: 45585 | W5: Processed | AA5: =COUNTBLANK(V2:V347) -> 166 | AB5: =COUNTIF(A$2:A$347,A5) -> 1 | AC5: =LEN(S5)-LEN(TRIM(S5)) -> 0 | AD5: =LEN(E5)-LEN(SUBSTITUTE(E5,"-","")) -> 2 | AE5: =IF(I5>10,"FLAG","OK") -> OK | AF5: =IF(OR(H5<=0,H5>10000),"FLAG","OK") -> OK | AG5: =IF(OR(L5<0,L5>100),"FLAG","OK") -> OK | AI5: =IF(AG5=J5,"OK","ERROR") -> ERROR | AJ5: =IF(R5<B5,"ERROR","OK") -> OK | AK5: =IF(AND(S5="Cancelled",R5<>""),"ERROR","OK") -> OK | AL5: =IF(AND(T5="Yes",U5=""),"ERROR","OK") -> OK | AM5: =IF(V5<R5,"ERROR","OK") -> OK | AN5: =IF(AND(I5>0,MOD(I5,1)=0),"OK","ERROR") -> OK | AO5: =IF(OR(B5="",B5<DATE(2024,10,1),B5>DATE(2024,12,31)),"ERROR","OK") -> OK | AP5: =IF(OR(B5<DATE(2024,10,1),B5>DATE(2024,12,31)),"ERROR","OK") -> OK | AQ5: =IF(OR(S5="Delivered",S5="Cancelled",S5="RTO",S5="In Transit"),"OK","ERROR") -> OK
A6: UT-100005 | B6: 45566 | C6: CUST_10001 | D6: New | E6: ACC-SCF-OS | F6: Accessories | G6: Silk Scarf | H6: 799 | I6: 3 | J6: 2397 | L6: 0 | M6: UPI | N6: Website | O6: Mumbai | P6: Maharashtra | Q6: Mumbai | R6: 45571 | S6: Delivered | T6: No | W6: Not Applicable | AB6: =COUNTIF(A$2:A$347,A6) -> 1 | AC6: =LEN(S6)-LEN(TRIM(S6)) -> 0 | AD6: =LEN(E6)-LEN(SUBSTITUTE(E6,"-","")) -> 2 | AE6: =IF(I6>10,"FLAG","OK") -> OK | AF6: =IF(OR(H6<=0,H6>10000),"FLAG","OK") -> OK | AG6: =IF(OR(L6<0,L6>100),"FLAG","OK") -> OK | AI6: =IF(AG6=J6,"OK","ERROR") -> ERROR | AJ6: =IF(R6<B6,"ERROR","OK") -> OK | AK6: =IF(AND(S6="Cancelled",R6<>""),"ERROR","OK") -> OK | AL6: =IF(AND(T6="Yes",U6=""),"ERROR","OK") -> OK | AM6: =IF(V6<R6,"ERROR","OK") -> ERROR | AN6: =IF(AND(I6>0,MOD(I6,1)=0),"OK","ERROR") -> OK | AO6: =IF(OR(B6="",B6<DATE(2024,10,1),B6>DATE(2024,12,31)),"ERROR","OK") -> OK | AP6: =IF(OR(B6<DATE(2024,10,1),B6>DATE(2024,12,31)),"ERROR","OK") -> OK | AQ6: =IF(OR(S6="Delivered",S6="Cancelled",S6="RTO",S6="In Transit"),"OK","ERROR") -> OK
A7: UT-100006 | B7: 45567 | C7: CUST_10005 | D7: Returning | E7: TOP-FRM-S | F7: Tops | G7: Printed Blouse | H7: 1599 | I7: 2 | J7: 3198 | L7: 0 | M7: Credit Card | N7: Mobile App | O7: Hyderabad | P7: Telangana | Q7: Bangalore | R7: 45572 | S7: Delivered | T7: Yes | U7: Changed Mind | V7: 45583 | W7: Processed | AB7: =COUNTIF(A$2:A$347,A7) -> 1 | AC7: =LEN(S7)-LEN(TRIM(S7)) -> 0 | AD7: =LEN(E7)-LEN(SUBSTITUTE(E7,"-","")) -> 2 | AE7: =IF(I7>10,"FLAG","OK") -> OK | AF7: =IF(OR(H7<=0,H7>10000),"FLAG","OK") -> OK | AG7: =IF(OR(L7<0,L7>100),"FLAG","OK") -> OK | AI7: =IF(AG7=J7,"OK","ERROR") -> ERROR | AJ7: =IF(R7<B7,"ERROR","OK") -> OK | AK7: =IF(AND(S7="Cancelled",R7<>""),"ERROR","OK") -> OK | AL7: =IF(AND(T7="Yes",U7=""),"ERROR","OK") -> OK | AM7: =IF(V7<R7,"ERROR","OK") -> OK | AN7: =IF(AND(I7>0,MOD(I7,1)=0),"OK","ERROR") -> OK | AO7: =IF(OR(B7="",B7<DATE(2024,10,1),B7>DATE(2024,12,31)),"ERROR","OK") -> OK | AP7: =IF(OR(B7<DATE(2024,10,1),B7>DATE(2024,12,31)),"ERROR","OK") -> OK | AQ7: =IF(OR(S7="Delivered",S7="Cancelled",S7="RTO",S7="In Transit"),"OK","ERROR") -> OK
A8: UT-100007 | B8: 45567 | C8: CUST_10006 | D8: New | E8: DRS-CAS-M | F8: Dresses | G8: A-Line Dress | H8: 2199 | I8: 1 | J8: 2199 | K8: DIWALI20 | L8: 20 | M8: COD | N8: Website | O8: Pune | P8: Maharashtra | Q8: Mumbai | S8: Cancelled | T8: No | W8: Not Applicable | AB8: =COUNTIF(A$2:A$347,A8) -> 1 | AC8: =LEN(S8)-LEN(TRIM(S8)) -> 0 | AD8: =LEN(E8)-LEN(SUBSTITUTE(E8,"-","")) -> 2 | AE8: =IF(I8>10,"FLAG","OK") -> OK | AF8: =IF(OR(H8<=0,H8>10000),"FLAG","OK") -> OK | AG8: =IF(OR(L8<0,L8>100),"FLAG","OK") -> OK | AI8: =IF(AG8=J8,"OK","ERROR") -> ERROR | AJ8: =IF(R8<B8,"ERROR","OK") -> ERROR | AK8: =IF(AND(S8="Cancelled",R8<>""),"ERROR","OK") -> OK | AL8: =IF(AND(T8="Yes",U8=""),"ERROR","OK") -> OK | AM8: =IF(V8<R8,"ERROR","OK") -> OK | AN8: =IF(AND(I8>0,MOD(I8,1)=0),"OK","ERROR") -> OK | AO8: =IF(OR(B8="",B8<DATE(2024,10,1),B8>DATE(2024,12,31)),"ERROR","OK") -> OK | AP8: =IF(OR(B8<DATE(2024,10,1),B8>DATE(2024,12,31)),"ERROR","OK") -> OK | AQ8: =IF(OR(S8="Delivered",S8="Cancelled",S8="RTO",S8="In Transit"),"OK","ERROR") -> OK
A9: UT-100008 | B9: 45567 | C9: CUST_10007 | D9: New | E9: BOT-TRS-L | F9: Bottoms | G9: Formal Trousers | H9: 2299 | I9: 1 | J9: 2299 | L9: 0 | M9: UPI | N9: Mobile App | O9: Kolkata | P9: West Bengal | Q9: Delhi | R9: 45575 | S9: Delivered | T9: No | W9: Not Applicable | AB9: =COUNTIF(A$2:A$347,A9) -> 1 | AC9: =LEN(S9)-LEN(TRIM(S9)) -> 0 | AD9: =LEN(E9)-LEN(SUBSTITUTE(E9,"-","")) -> 2 | AE9: =IF(I9>10,"FLAG","OK") -> OK | AF9: =IF(OR(H9<=0,H9>10000),"FLAG","OK") -> OK | AG9: =IF(OR(L9<0,L9>100),"FLAG","OK") -> OK | AI9: =IF(AG9=J9,"OK","ERROR") -> ERROR | AJ9: =IF(R9<B9,"ERROR","OK") -> OK | AK9: =IF(AND(S9="Cancelled",R9<>""),"ERROR","OK") -> OK | AL9: =IF(AND(T9="Yes",U9=""),"ERROR","OK") -> OK | AM9: =IF(V9<R9,"ERROR","OK") -> ERROR | AN9: =IF(AND(I9>0,MOD(I9,1)=0),"OK","ERROR") -> OK | AO9: =IF(OR(B9="",B9<DATE(2024,10,1),B9>DATE(2024,12,31)),"ERROR","OK") -> OK | AP9: =IF(OR(B9<DATE(2024,10,1),B9>DATE(2024,12,31)),"ERROR","OK") -> OK | AQ9: =IF(OR(S9="Delivered",S9="Cancelled",S9="RTO",S9="In Transit"),"OK","ERROR") -> OK
A10: UT-100009 | B10: 45567 | C10: CUST_10008 | D10: Returning | E10: TOP-CAS-XL | F10: Tops | G10: Oversized Tee | H10: 1399 | I10: 5 | J10: 6995 | L10: 0 | M10: Credit Card | N10: Website | O10: Ahmedabad | P10: Gujarat | Q10: Mumbai | R10: 45574 | S10: Delivered | T10: Yes | U10: Size Issue | V10: 45587 | W10: Processed | AB10: =COUNTIF(A$2:A$347,A10) -> 1 | AC10: =LEN(S10)-LEN(TRIM(S10)) -> 0 | AD10: =LEN(E10)-LEN(SUBSTITUTE(E10,"-","")) -> 2 | AE10: =IF(I10>10,"FLAG","OK") -> OK | AF10: =IF(OR(H10<=0,H10>10000),"FLAG","OK") -> OK | AG10: =IF(OR(L10<0,L10>100),"FLAG","OK") -> OK | AI10: =IF(AG10=J10,"OK","ERROR") -> ERROR | AJ10: =IF(R10<B10,"ERROR","OK") -> OK | AK10: =IF(AND(S10="Cancelled",R10<>""),"ERROR","OK") -> OK | AL10: =IF(AND(T10="Yes",U10=""),"ERROR","OK") -> OK | AM10: =IF(V10<R10,"ERROR","OK") -> OK | AN10: =IF(AND(I10>0,MOD(I10,1)=0),"OK","ERROR") -> OK | AO10: =IF(OR(B10="",B10<DATE(2024,10,1),B10>DATE(2024,12,31)),"ERROR","OK") -> OK | AP10: =IF(OR(B10<DATE(2024,10,1),B10>DATE(2024,12,31)),"ERROR","OK") -> OK | AQ10: =IF(OR(S10="Delivered",S10="Cancelled",S10="RTO",S10="In Transit"),"OK","ERROR") -> OK
A11: UT-100010 | B11: 45567 | C11: CUST_10009 | D11: New | E11: OUT-BLZ-M | F11: Outerwear | G11: Casual Blazer | H11: 4999 | I11: -1 | J11: 4999 | L11: 0 | M11: Debit Card | N11: Instagram Shop | O11: Jaipur | P11: Rajasthan | Q11: Delhi | R11: 45576 | S11: Delivered | T11: Yes | U11: Wrong Item | V11: 45590 | W11: Pending | AB11: =COUNTIF(A$2:A$347,A11) -> 1 | AC11: =LEN(S11)-LEN(TRIM(S11)) -> 0 | AD11: =LEN(E11)-LEN(SUBSTITUTE(E11,"-","")) -> 2 | AE11: =IF(I11>10,"FLAG","OK") -> OK | AF11: =IF(OR(H11<=0,H11>10000),"FLAG","OK") -> OK | AG11: =IF(OR(L11<0,L11>100),"FLAG","OK") -> OK | AI11: =IF(AG11=J11,"OK","ERROR") -> ERROR | AJ11: =IF(R11<B11,"ERROR","OK") -> OK | AK11: =IF(AND(S11="Cancelled",R11<>""),"ERROR","OK") -> OK | AL11: =IF(AND(T11="Yes",U11=""),"ERROR","OK") -> OK | AM11: =IF(V11<R11,"ERROR","OK") -> OK | AN11: =IF(AND(I11>0,MOD(I11,1)=0),"OK","ERROR") -> ERROR | AO11: =IF(OR(B11="",B11<DATE(2024,10,1),B11>DATE(2024,12,31)),"ERROR","OK") -> OK | AP11: =IF(OR(B11<DATE(2024,10,1),B11>DATE(2024,12,31)),"ERROR","OK") -> OK | AQ11: =IF(OR(S11="Delivered",S11="Cancelled",S11="RTO",S11="In Transit"),"OK","ERROR") -> OK
A12: UT-100011 | B12: 45568 | C12: CUST_10010 | D12: New | E12: ACC-BAG-OS | F12: Accessories | G12: Tote Bag | H12: 1299 | I12: 2 | J12: 2598 | K12: FLAT10 | L12: 10 | M12: Wallet | N12: Website | O12: Lucknow | P12: Uttar Pradesh | Q12: Delhi | R12: 45575 | S12: Delivered | T12: No | W12: Not Applicable | AB12: =COUNTIF(A$2:A$347,A12) -> 1 | AC12: =LEN(S12)-LEN(TRIM(S12)) -> 0 | AD12: =LEN(E12)-LEN(SUBSTITUTE(E12,"-","")) -> 2 | AE12: =IF(I12>10,"FLAG","OK") -> OK | AF12: =IF(OR(H12<=0,H12>10000),"FLAG","OK") -> OK | AG12: =IF(OR(L12<0,L12>100),"FLAG","OK") -> OK | AI12: =IF(AG12=J12,"OK","ERROR") -> ERROR | AJ12: =IF(R12<B12,"ERROR","OK") -> OK | AK12: =IF(AND(S12="Cancelled",R12<>""),"ERROR","OK") -> OK | AL12: =IF(AND(T12="Yes",U12=""),"ERROR","OK") -> OK | AM12: =IF(V12<R12,"ERROR","OK") -> ERROR | AN12: =IF(AND(I12>0,MOD(I12,1)=0),"OK","ERROR") -> OK | AO12: =IF(OR(B12="",B12<DATE(2024,10,1),B12>DATE(2024,12,31)),"ERROR","OK") -> OK | AP12: =IF(OR(B12<DATE(2024,10,1),B12>DATE(2024,12,31)),"ERROR","OK") -> OK | AQ12: =IF(OR(S12="Delivered",S12="Cancelled",S12="RTO",S12="In Transit"),"OK","ERROR") -> OK
A13: UT-100012 | B13: 45568 | C13: CUST_10011 | D13: New | E13: DRS-PRT-S | F13: Dresses | G13: Party Dress | H13: 3299 | I13: 1 | J13: 3299 | L13: 0 | M13: COD | N13: Mobile App | O13: Chandigarh | P13: Punjab | Q13: Delhi | S13: RTO | T13: No | W13: Not Applicable | AB13: =COUNTIF(A$2:A$347,A13) -> 1 | AC13: =LEN(S13)-LEN(TRIM(S13)) -> 0 | AD13: =LEN(E13)-LEN(SUBSTITUTE(E13,"-","")) -> 2 | AE13: =IF(I13>10,"FLAG","OK") -> OK | AF13: =IF(OR(H13<=0,H13>10000),"FLAG","OK") -> OK | AG13: =IF(OR(L13<0,L13>100),"FLAG","OK") -> OK | AI13: =IF(AG13=J13,"OK","ERROR") -> ERROR | AJ13: =IF(R13<B13,"ERROR","OK") -> ERROR | AK13: =IF(AND(S13="Cancelled",R13<>""),"ERROR","OK") -> OK | AL13: =IF(AND(T13="Yes",U13=""),"ERROR","OK") -> OK | AM13: =IF(V13<R13,"ERROR","OK") -> OK | AN13: =IF(AND(I13>0,MOD(I13,1)=0),"OK","ERROR") -> OK | AO13: =IF(OR(B13="",B13<DATE(2024,10,1),B13>DATE(2024,12,31)),"ERROR","OK") -> OK | AP13: =IF(OR(B13<DATE(2024,10,1),B13>DATE(2024,12,31)),"ERROR","OK") -> OK | AQ13: =IF(OR(S13="Delivered",S13="Cancelled",S13="RTO",S13="In Transit"),"OK","ERROR") -> OK
A14: UT-100013 | B14: 45568 | C14: CUST_10012 | D14: Returning | E14: TOP-SLK-M | F14: Tops | G14: Silk Blouse | H14: 2499 | I14: 1 | J14: 2499 | L14: 0 | M14: Credit Card | N14: Website | O14: Mumbai | P14: Maharashtra | Q14: Mumbai | R14: 45574 | S14: Delivered | T14: No | W14: Not Applicable | AB14: =COUNTIF(A$2:A$347,A14) -> 1 | AC14: =LEN(S14)-LEN(TRIM(S14)) -> 0 | AD14: =LEN(E14)-LEN(SUBSTITUTE(E14,"-","")) -> 2 | AE14: =IF(I14>10,"FLAG","OK") -> OK | AF14: =IF(OR(H14<=0,H14>10000),"FLAG","OK") -> OK | AG14: =IF(OR(L14<0,L14>100),"FLAG","OK") -> OK | AI14: =IF(AG14=J14,"OK","ERROR") -> ERROR | AJ14: =IF(R14<B14,"ERROR","OK") -> OK | AK14: =IF(AND(S14="Cancelled",R14<>""),"ERROR","OK") -> OK | AL14: =IF(AND(T14="Yes",U14=""),"ERROR","OK") -> OK | AM14: =IF(V14<R14,"ERROR","OK") -> ERROR | AN14: =IF(AND(I14>0,MOD(I14,1)=0),"OK","ERROR") -> OK | AO14: =IF(OR(B14="",B14<DATE(2024,10,1),B14>DATE(2024,12,31)),"ERROR","OK") -> OK | AP14: =IF(OR(B14<DATE(2024,10,1),B14>DATE(2024,12,31)),"ERROR","OK") -> OK | AQ14: =IF(OR(S14="Delivered",S14="Cancelled",S14="RTO",S14="In Transit"),"OK","ERROR") -> OK
A15: UT-100014 | B15: 45568 | C15: CUST_10013 | D15: New | E15: BOT-SKT-S | F15: Bottoms | G15: Pleated Skirt | H15: 1799 | I15: 2 | J15: 3598 | K15: DIWALI20 | L15: 20 | M15: UPI | N15: Instagram Shop | O15: Delhi | P15: Delhi | Q15: Delhi | R15: 45576 | S15: Delivered | T15: Yes | U15: Size Issue | V15: 45593 | W15: Processed | AB15: =COUNTIF(A$2:A$347,A15) -> 1 | AC15: =LEN(S15)-LEN(TRIM(S15)) -> 0 | AD15: =LEN(E15)-LEN(SUBSTITUTE(E15,"-","")) -> 2 | AE15: =IF(I15>10,"FLAG","OK") -> OK | AF15: =IF(OR(H15<=0,H15>10000),"FLAG","OK") -> OK | AG15: =IF(OR(L15<0,L15>100),"FLAG","OK") -> OK | AI15: =IF(AG15=J15,"OK","ERROR") -> ERROR | AJ15: =IF(R15<B15,"ERROR","OK") -> OK | AK15: =IF(AND(S15="Cancelled",R15<>""),"ERROR","OK") -> OK | AL15: =IF(AND(T15="Yes",U15=""),"ERROR","OK") -> OK | AM15: =IF(V15<R15,"ERROR","OK") -> OK | AN15: =IF(AND(I15>0,MOD(I15,1)=0),"OK","ERROR") -> OK | AO15: =IF(OR(B15="",B15<DATE(2024,10,1),B15>DATE(2024,12,31)),"ERROR","OK") -> OK | AP15: =IF(OR(B15<DATE(2024,10,1),B15>DATE(2024,12,31)),"ERROR","OK") -> OK | AQ15: =IF(OR(S15="Delivered",S15="Cancelled",S15="RTO",S15="In Transit"),"OK","ERROR") -> OK
A16: UT-100015 | B16: 45568 | C16: CUST_10014 | D16: New | E16: OUT-CRD-L | F16: Outerwear | G16: Knit Cardigan | H16: 2799 | I16: 1 | J16: 2799 | L16: 0 | M16: Debit Card | N16: Mobile App | O16: Bangalore | P16: Karnataka | Q16: Bangalore | R16: 45577 | S16: Delivered | T16: No | W16: Not Applicable | AB16: =COUNTIF(A$2:A$347,A16) -> 1 | AC16: =LEN(S16)-LEN(TRIM(S16)) -> 0 | AD16: =LEN(E16)-LEN(SUBSTITUTE(E16,"-","")) -> 2 | AE16: =IF(I16>10,"FLAG","OK") -> OK | AF16: =IF(OR(H16<=0,H16>10000),"FLAG","OK") -> OK | AG16: =IF(OR(L16<0,L16>100),"FLAG","OK") -> OK | AI16: =IF(AG16=J16,"OK","ERROR") -> ERROR | AJ16: =IF(R16<B16,"ERROR","OK") -> OK | AK16: =IF(AND(S16="Cancelled",R16<>""),"ERROR","OK") -> OK | AL16: =IF(AND(T16="Yes",U16=""),"ERROR","OK") -> OK | AM16: =IF(V16<R16,"ERROR","OK") -> ERROR | AN16: =IF(AND(I16>0,MOD(I16,1)=0),"OK","ERROR") -> OK | AO16: =IF(OR(B16="",B16<DATE(2024,10,1),B16>DATE(2024,12,31)),"ERROR","OK") -> OK | AP16: =IF(OR(B16<DATE(2024,10,1),B16>DATE(2024,12,31)),"ERROR","OK") -> OK | AQ16: =IF(OR(S16="Delivered",S16="Cancelled",S16="RTO",S16="In Transit"),"OK","ERROR") -> OK
A17: UT-100016 | B17: 45569 | C17: CUST_10015 | D17: Returning | E17: ACC-JWL-OS | F17: Accessories | G17: Statement Earrings | H17: 599 | I17: 4 | J17: 2396 | L17: 0 | M17: COD | N17: Website | O17: Noida | P17: Uttar Pradesh | Q17: Delhi | R17: 45579 | S17: Delivered | T17: Yes | U17: Damaged in Transit | V17: 45591 | W17: Processed | AB17: =COUNTIF(A$2:A$347,A17) -> 1 | AC17: =LEN(S17)-LEN(TRIM(S17)) -> 0 | AD17: =LEN(E17)-LEN(SUBSTITUTE(E17,"-","")) -> 2 | AE17: =IF(I17>10,"FLAG","OK") -> OK | AF17: =IF(OR(H17<=0,H17>10000),"FLAG","OK") -> OK | AG17: =IF(OR(L17<0,L17>100),"FLAG","OK") -> OK | AI17: =IF(AG17=J17,"OK","ERROR") -> ERROR | AJ17: =IF(R17<B17,"ERROR","OK") -> OK | AK17: =IF(AND(S17="Cancelled",R17<>""),"ERROR","OK") -> OK | AL17: =IF(AND(T17="Yes",U17=""),"ERROR","OK") -> OK | AM17: =IF(V17<R17,"ERROR","OK") -> OK | AN17: =IF(AND(I17>0,MOD(I17,1)=0),"OK","ERROR") -> OK | AO17: =IF(OR(B17="",B17<DATE(2024,10,1),B17>DATE(2024,12,31)),"ERROR","OK") -> OK | AP17: =IF(OR(B17<DATE(2024,10,1),B17>DATE(2024,12,31)),"ERROR","OK") -> OK | AQ17: =IF(OR(S17="Delivered",S17="Cancelled",S17="RTO",S17="In Transit"),"OK","ERROR") -> OK
A18: UT-100017 | B18: 45569 | C18: CUST_10016 | D18: New | E18: TOP-CRP-XS | F18: Tops | G18: Crop Top | H18: 999 | I18: 1 | J18: 999 | K18: FIRST15 | L18: 15 | M18: UPI | N18: Mobile App | O18: Gurgaon | P18: Haryana | Q18: Delhi | R18: 45577 | S18: Delievered | T18: No | W18: Not Applicable | AB18: =COUNTIF(A$2:A$347,A18) -> 1 | AC18: =LEN(S18)-LEN(TRIM(S18)) -> 0 | AD18: =LEN(E18)-LEN(SUBSTITUTE(E18,"-","")) -> 2 | AE18: =IF(I18>10,"FLAG","OK") -> OK | AF18: =IF(OR(H18<=0,H18>10000),"FLAG","OK") -> OK | AG18: =IF(OR(L18<0,L18>100),"FLAG","OK") -> OK | AI18: =IF(AG18=J18,"OK","ERROR") -> ERROR | AJ18: =IF(R18<B18,"ERROR","OK") -> OK | AK18: =IF(AND(S18="Cancelled",R18<>""),"ERROR","OK") -> OK | AL18: =IF(AND(T18="Yes",U18=""),"ERROR","OK") -> OK | AM18: =IF(V18<R18,"ERROR","OK") -> ERROR | AN18: =IF(AND(I18>0,MOD(I18,1)=0),"OK","ERROR") -> OK | AO18: =IF(OR(B18="",B18<DATE(2024,10,1),B18>DATE(2024,12,31)),"ERROR","OK") -> OK | AP18: =IF(OR(B18<DATE(2024,10,1),B18>DATE(2024,12,31)),"ERROR","OK") -> OK | AQ18: =IF(OR(S18="Delivered",S18="Cancelled",S18="RTO",S18="In Transit"),"OK","ERROR") -> ERROR
A19: UT-100018 | B19: 45569 | C19: CUST_10017 | D19: New | E19: DRS-MAX-M | F19: Dresses | G19: Maxi Dress | H19: 2899 | I19: 1 | J19: 2899 | L19: 0 | M19: Credit Card | N19: Website | O19: Indore | P19: Madhya Pradesh | Q19: Mumbai | R19: 45579 | S19: Delivered | T19: No | W19: Not Applicable | AB19: =COUNTIF(A$2:A$347,A19) -> 1 | AC19: =LEN(S19)-LEN(TRIM(S19)) -> 0 | AD19: =LEN(E19)-LEN(SUBSTITUTE(E19,"-","")) -> 2 | AE19: =IF(I19>10,"FLAG","OK") -> OK | AF19: =IF(OR(H19<=0,H19>10000),"FLAG","OK") -> OK | AG19: =IF(OR(L19<0,L19>100),"FLAG","OK") -> OK | AI19: =IF(AG19=J19,"OK","ERROR") -> ERROR | AJ19: =IF(R19<B19,"ERROR","OK") -> OK | AK19: =IF(AND(S19="Cancelled",R19<>""),"ERROR","OK") -> OK | AL19: =IF(AND(T19="Yes",U19=""),"ERROR","OK") -> OK | AM19: =IF(V19<R19,"ERROR","OK") -> ERROR | AN19: =IF(AND(I19>0,MOD(I19,1)=0),"OK","ERROR") -> OK | AO19: =IF(OR(B19="",B19<DATE(2024,10,1),B19>DATE(2024,12,31)),"ERROR","OK") -> OK | AP19: =IF(OR(B19<DATE(2024,10,1),B19>DATE(2024,12,31)),"ERROR","OK") -> OK | AQ19: =IF(OR(S19="Delivered",S19="Cancelled",S19="RTO",S19="In Transit"),"OK","ERROR") -> OK
A20: UT-100019 | B20: 45569 | C20: CUST_10018 | D20: Returning | E20: BOT-JGR-M | F20: Bottoms | G20: Joggers | H20: 1499 | I20: 2 | J20: 2998 | L20: 0 | M20: Wallet | N20: Instagram Shop | O20: Surat | P20: Gujarat | Q20: Mumbai | R20: 45578 | S20: Delivered | T20: Yes | U20: Size Issue | V20: 45595 | W20: Processed | AB20: =COUNTIF(A$2:A$347,A20) -> 1 | AC20: =LEN(S20)-LEN(TRIM(S20)) -> 0 | AD20: =LEN(E20)-LEN(SUBSTITUTE(E20,"-","")) -> 2 | AE20: =IF(I20>10,"FLAG","OK") -> OK | AF20: =IF(OR(H20<=0,H20>10000),"FLAG","OK") -> OK | AG20: =IF(OR(L20<0,L20>100),"FLAG","OK") -> OK | AI20: =IF(AG20=J20,"OK","ERROR") -> ERROR | AJ20: =IF(R20<B20,"ERROR","OK") -> OK | AK20: =IF(AND(S20="Cancelled",R20<>""),"ERROR","OK") -> OK | AL20: =IF(AND(T20="Yes",U20=""),"ERROR","OK") -> OK | AM20: =IF(V20<R20,"ERROR","OK") -> OK | AN20: =IF(AND(I20>0,MOD(I20,1)=0),"OK","ERROR") -> OK | AO20: =IF(OR(B20="",B20<DATE(2024,10,1),B20>DATE(2024,12,31)),"ERROR","OK") -> OK | AP20: =IF(OR(B20<DATE(2024,10,1),B20>DATE(2024,12,31)),"ERROR","OK") -> OK | AQ20: =IF(OR(S20="Delivered",S20="Cancelled",S20="RTO",S20="In Transit"),"OK","ERROR") -> OK
A21: UT-100020 | B21: 45570 | C21: CUST_10019 | D21: New | E21: OUT-VST-S | F21: Outerwear | G21: Puffer Vest | H21: 3999 | I21: 1 | J21: 3999 | K21: DIWALI20 | L21: 20 | M21: COD | N21: Website | O21: Patna | P21: Bihar | Q21: Delhi | S21: RTO | T21: No | W21: Not Applicable | AB21: =COUNTIF(A$2:A$347,A21) -> 1 | AC21: =LEN(S21)-LEN(TRIM(S21)) -> 0 | AD21: =LEN(E21)-LEN(SUBSTITUTE(E21,"-","")) -> 2 | AE21: =IF(I21>10,"FLAG","OK") -> OK | AF21: =IF(OR(H21<=0,H21>10000),"FLAG","OK") -> OK | AG21: =IF(OR(L21<0,L21>100),"FLAG","OK") -> OK | AI21: =IF(AG21=J21,"OK","ERROR") -> ERROR | AJ21: =IF(R21<B21,"ERROR","OK") -> ERROR | AK21: =IF(AND(S21="Cancelled",R21<>""),"ERROR","OK") -> OK | AL21: =IF(AND(T21="Yes",U21=""),"ERROR","OK") -> OK | AM21: =IF(V21<R21,"ERROR","OK") -> OK | AN21: =IF(AND(I21>0,MOD(I21,1)=0),"OK","ERROR") -> OK | AO21: =IF(OR(B21="",B21<DATE(2024,10,1),B21>DATE(2024,12,31)),"ERROR","OK") -> OK | AP21: =IF(OR(B21<DATE(2024,10,1),B21>DATE(2024,12,31)),"ERROR","OK") -> OK | AQ21: =IF(OR(S21="Delivered",S21="Cancelled",S21="RTO",S21="In Transit"),"OK","ERROR") -> OK
A22: UT-100021 | B22: 45570 | C22: CUST_10020 | D22: New | E22: TOP-TUN-L | F22: Tops | G22: Tunic Top | H22: 1699 | I22: 1 | J22: 1699 | L22: 0 | M22: UPI | N22: Mobile App | O22: Bhopal | P22: Madhya Pradesh | Q22: Mumbai | R22: 45580 | S22: Delivered | T22: No | W22: Not Applicable | AB22: =COUNTIF(A$2:A$347,A22) -> 1 | AC22: =LEN(S22)-LEN(TRIM(S22)) -> 0 | AD22: =LEN(E22)-LEN(SUBSTITUTE(E22,"-","")) -> 2 | AE22: =IF(I22>10,"FLAG","OK") -> OK | AF22: =IF(OR(H22<=0,H22>10000),"FLAG","OK") -> OK | AG22: =IF(OR(L22<0,L22>100),"FLAG","OK") -> OK | AI22: =IF(AG22=J22,"OK","ERROR") -> ERROR | AJ22: =IF(R22<B22,"ERROR","OK") -> OK | AK22: =IF(AND(S22="Cancelled",R22<>""),"ERROR","OK") -> OK | AL22: =IF(AND(T22="Yes",U22=""),"ERROR","OK") -> OK | AM22: =IF(V22<R22,"ERROR","OK") -> ERROR | AN22: =IF(AND(I22>0,MOD(I22,1)=0),"OK","ERROR") -> OK | AO22: =IF(OR(B22="",B22<DATE(2024,10,1),B22>DATE(2024,12,31)),"ERROR","OK") -> OK | AP22: =IF(OR(B22<DATE(2024,10,1),B22>DATE(2024,12,31)),"ERROR","OK") -> OK | AQ22: =IF(OR(S22="Delivered",S22="Cancelled",S22="RTO",S22="In Transit"),"OK","ERROR") -> OK
A23: UT-100022 | B23: 45570 | C23: CUST_10021 | D23: Returning | E23: DRS-SHT-XS | F23: Dresses | G23: Shirt Dress | H23: 2399 | I23: 1 | J23: 2399 | L23: 0 | M23: Credit Card | N23: Website | O23: Nagpur | P23: Maharashtra | Q23: Mumbai | R23: 45581 | S23: Delivered | T23: Yes | U23: Quality Defect | V23: 45598 | W23: Processed | AB23: =COUNTIF(A$2:A$347,A23) -> 1 | AC23: =LEN(S23)-LEN(TRIM(S23)) -> 0 | AD23: =LEN(E23)-LEN(SUBSTITUTE(E23,"-","")) -> 2 | AE23: =IF(I23>10,"FLAG","OK") -> OK | AF23: =IF(OR(H23<=0,H23>10000),"FLAG","OK") -> OK | AG23: =IF(OR(L23<0,L23>100),"FLAG","OK") -> OK | AI23: =IF(AG23=J23,"OK","ERROR") -> ERROR | AJ23: =IF(R23<B23,"ERROR","OK") -> OK | AK23: =IF(AND(S23="Cancelled",R23<>""),"ERROR","OK") -> OK | AL23: =IF(AND(T23="Yes",U23=""),"ERROR","OK") -> OK | AM23: =IF(V23<R23,"ERROR","OK") -> OK | AN23: =IF(AND(I23>0,MOD(I23,1)=0),"OK","ERROR") -> OK | AO23: =IF(OR(B23="",B23<DATE(2024,10,1),B23>DATE(2024,12,31)),"ERROR","OK") -> OK | AP23: =IF(OR(B23<DATE(2024,10,1),B23>DATE(2024,12,31)),"ERROR","OK") -> OK | AQ23: =IF(OR(S23="Delivered",S23="Cancelled",S23="RTO",S23="In Transit"),"OK","ERROR") -> OK
A24: UT-100023 | B24: 45570 | C24: CUST_10022 | D24: New | E24: ACC-BLT-M | F24: Accessories | G24: Leather Belt | H24: 899 | I24: 1 | J24: 899 | K24: FLAT10 | L24: 10 | M24: Debit Card | N24: Mobile App | O24: Coimbatore | P24: Tamil Nadu | Q24: Bangalore | R24: 45582 | S24: Delivered | T24: No | W24: Not Applicable | AB24: =COUNTIF(A$2:A$347,A24) -> 1 | AC24: =LEN(S24)-LEN(TRIM(S24)) -> 0 | AD24: =LEN(E24)-LEN(SUBSTITUTE(E24,"-","")) -> 2 | AE24: =IF(I24>10,"FLAG","OK") -> OK | AF24: =IF(OR(H24<=0,H24>10000),"FLAG","OK") -> OK | AG24: =IF(OR(L24<0,L24>100),"FLAG","OK") -> OK | AI24: =IF(AG24=J24,"OK","ERROR") -> ERROR | AJ24: =IF(R24<B24,"ERROR","OK") -> OK | AK24: =IF(AND(S24="Cancelled",R24<>""),"ERROR","OK") -> OK | AL24: =IF(AND(T24="Yes",U24=""),"ERROR","OK") -> OK | AM24: =IF(V24<R24,"ERROR","OK") -> ERROR | AN24: =IF(AND(I24>0,MOD(I24,1)=0),"OK","ERROR") -> OK | AO24: =IF(OR(B24="",B24<DATE(2024,10,1),B24>DATE(2024,12,31)),"ERROR","OK") -> OK | AP24: =IF(OR(B24<DATE(2024,10,1),B24>DATE(2024,12,31)),"ERROR","OK") -> OK | AQ24: =IF(OR(S24="Delivered",S24="Cancelled",S24="RTO",S24="In Transit"),"OK","ERROR") -> OK
A25: UT-100024 | B25: 45571 | C25: CUST_10023 | D25: New | E25: BOT-SHT-M | F25: Bottoms | G25: Cotton Shorts | H25: 1199 | I25: 3 | J25: 3597 | L25: 0 | M25: COD | N25: Instagram Shop | O25: Kochi | P25: Kerala | Q25: Bangalore | R25: 45583 | S25: Delivered | T25: Yes | U25: Changed Mind | V25: 45601 | W25: Processed | AB25: =COUNTIF(A$2:A$347,A25) -> 1 | AC25: =LEN(S25)-LEN(TRIM(S25)) -> 0 | AD25: =LEN(E25)-LEN(SUBSTITUTE(E25,"-","")) -> 2 | AE25: =IF(I25>10,"FLAG","OK") -> OK | AF25: =IF(OR(H25<=0,H25>10000),"FLAG","OK") -> OK | AG25: =IF(OR(L25<0,L25>100),"FLAG","OK") -> OK | AI25: =IF(AG25=J25,"OK","ERROR") -> ERROR | AJ25: =IF(R25<B25,"ERROR","OK") -> OK | AK25: =IF(AND(S25="Cancelled",R25<>""),"ERROR","OK") -> OK | AL25: =IF(AND(T25="Yes",U25=""),"ERROR","OK") -> OK | AM25: =IF(V25<R25,"ERROR","OK") -> OK | AN25: =IF(AND(I25>0,MOD(I25,1)=0),"OK","ERROR") -> OK | AO25: =IF(OR(B25="",B25<DATE(2024,10,1),B25>DATE(2024,12,31)),"ERROR","OK") -> OK | AP25: =IF(OR(B25<DATE(2024,10,1),B25>DATE(2024,12,31)),"ERROR","OK") -> OK | AQ25: =IF(OR(S25="Delivered",S25="Cancelled",S25="RTO",S25="In Transit"),"OK","ERROR") -> OK
A26: UT-100025 | B26: 45571 | C26: CUST_10024 | D26: New | E26: TOP-PLO-L | F26: Tops | G26: Polo Shirt | H26: 1799 | I26: 2 | J26: 3598 | L26: 0 | M26: UPI | N26: Website | O26: Vizag | P26: Andhra Pradesh | Q26: Bangalore | R26: 45582 | S26: Delivered | T26: No | W26: Not Applicable | AB26: =COUNTIF(A$2:A$347,A26) -> 1 | AC26: =LEN(S26)-LEN(TRIM(S26)) -> 0 | AD26: =LEN(E26)-LEN(SUBSTITUTE(E26,"-","")) -> 2 | AE26: =IF(I26>10,"FLAG","OK") -> OK | AF26: =IF(OR(H26<=0,H26>10000),"FLAG","OK") -> OK | AG26: =IF(OR(L26<0,L26>100),"FLAG","OK") -> OK | AI26: =IF(AG26=J26,"OK","ERROR") -> ERROR | AJ26: =IF(R26<B26,"ERROR","OK") -> OK | AK26: =IF(AND(S26="Cancelled",R26<>""),"ERROR","OK") -> OK | AL26: =IF(AND(T26="Yes",U26=""),"ERROR","OK") -> OK | AM26: =IF(V26<R26,"ERROR","OK") -> ERROR | AN26: =IF(AND(I26>0,MOD(I26,1)=0),"OK","ERROR") -> OK | AO26: =IF(OR(B26="",B26<DATE(2024,10,1),B26>DATE(2024,12,31)),"ERROR","OK") -> OK | AP26: =IF(OR(B26<DATE(2024,10,1),B26>DATE(2024,12,31)),"ERROR","OK") -> OK | AQ26: =IF(OR(S26="Delivered",S26="Cancelled",S26="RTO",S26="In Transit"),"OK","ERROR") -> OK
A27: UT-100026 | B27: 45571 | C27: CUST_10025 | D27: New | E27: DRS-WRK-M | F27: Dresses | G27: Work Dress | H27: 2699 | I27: 1 | J27: 2699 | L27: 0 | M27: Credit Card | N27: Mobile App | O27: Thiruvananthapuram | P27: Kerala | Q27: Bangalore | R27: 45583 | S27: Delivered | T27: No | W27: Not Applicable | AB27: =COUNTIF(A$2:A$347,A27) -> 1 | AC27: =LEN(S27)-LEN(TRIM(S27)) -> 0 | AD27: =LEN(E27)-LEN(SUBSTITUTE(E27,"-","")) -> 2 | AE27: =IF(I27>10,"FLAG","OK") -> OK | AF27: =IF(OR(H27<=0,H27>10000),"FLAG","OK") -> OK | AG27: =IF(OR(L27<0,L27>100),"FLAG","OK") -> OK | AI27: =IF(AG27=J27,"OK","ERROR") -> ERROR | AJ27: =IF(R27<B27,"ERROR","OK") -> OK | AK27: =IF(AND(S27="Cancelled",R27<>""),"ERROR","OK") -> OK | AL27: =IF(AND(T27="Yes",U27=""),"ERROR","OK") -> OK | AM27: =IF(V27<R27,"ERROR","OK") -> ERROR | AN27: =IF(AND(I27>0,MOD(I27,1)=0),"OK","ERROR") -> OK | AO27: =IF(OR(B27="",B27<DATE(2024,10,1),B27>DATE(2024,12,31)),"ERROR","OK") -> OK | AP27: =IF(OR(B27<DATE(2024,10,1),B27>DATE(2024,12,31)),"ERROR","OK") -> OK | AQ27: =IF(OR(S27="Delivered",S27="Cancelled",S27="RTO",S27="In Transit"),"OK","ERROR") -> OK
A28: UT-100027 | B28: 45571 | C28: CUST_10026 | D28: Returning | E28: OUT-TRN-L | F28: Outerwear | G28: Trench Coat | H28: 4599 | I28: 1 | J28: 4599 | K28: FLAT10 | L28: 10 | M28: Debit Card | N28: Website | O28: Mysore | P28: Karnataka | Q28: Bangalore | R28: 45584 | S28: Delivered | T28: Yes | U28: Size Issue | V28: 45604 | W28: Processed | AB28: =COUNTIF(A$2:A$347,A28) -> 1 | AC28: =LEN(S28)-LEN(TRIM(S28)) -> 0 | AD28: =LEN(E28)-LEN(SUBSTITUTE(E28,"-","")) -> 2 | AE28: =IF(I28>10,"FLAG","OK") -> OK | AF28: =IF(OR(H28<=0,H28>10000),"FLAG","OK") -> OK | AG28: =IF(OR(L28<0,L28>100),"FLAG","OK") -> OK | AI28: =IF(AG28=J28,"OK","ERROR") -> ERROR | AJ28: =IF(R28<B28,"ERROR","OK") -> OK | AK28: =IF(AND(S28="Cancelled",R28<>""),"ERROR","OK") -> OK | AL28: =IF(AND(T28="Yes",U28=""),"ERROR","OK") -> OK | AM28: =IF(V28<R28,"ERROR","OK") -> OK | AN28: =IF(AND(I28>0,MOD(I28,1)=0),"OK","ERROR") -> OK | AO28: =IF(OR(B28="",B28<DATE(2024,10,1),B28>DATE(2024,12,31)),"ERROR","OK") -> OK | AP28: =IF(OR(B28<DATE(2024,10,1),B28>DATE(2024,12,31)),"ERROR","OK") -> OK | AQ28: =IF(OR(S28="Delivered",S28="Cancelled",S28="RTO",S28="In Transit"),"OK","ERROR") -> OK
A29: UT-100028 | B29: 45572 | C29: CUST_10027 | D29: New | E29: ACC-HAT-OS | F29: Accessories | G29: Fedora Hat | H29: 1099 | I29: 1 | J29: 1099 | L29: 0 | M29: UPI | N29: Instagram Shop | O29: Vadodara | P29: Gujarat | Q29: Mumbai | R29: 45585 | S29: Delivered | T29: No | W29: Not Applicable | AB29: =COUNTIF(A$2:A$347,A29) -> 1 | AC29: =LEN(S29)-LEN(TRIM(S29)) -> 0 | AD29: =LEN(E29)-LEN(SUBSTITUTE(E29,"-","")) -> 2 | AE29: =IF(I29>10,"FLAG","OK") -> OK | AF29: =IF(OR(H29<=0,H29>10000),"FLAG","OK") -> OK | AG29: =IF(OR(L29<0,L29>100),"FLAG","OK") -> OK | AI29: =IF(AG29=J29,"OK","ERROR") -> ERROR | AJ29: =IF(R29<B29,"ERROR","OK") -> OK | AK29: =IF(AND(S29="Cancelled",R29<>""),"ERROR","OK") -> OK | AL29: =IF(AND(T29="Yes",U29=""),"ERROR","OK") -> OK | AM29: =IF(V29<R29,"ERROR","OK") -> ERROR | AN29: =IF(AND(I29>0,MOD(I29,1)=0),"OK","ERROR") -> OK | AO29: =IF(OR(B29="",B29<DATE(2024,10,1),B29>DATE(2024,12,31)),"ERROR","OK") -> OK | AP29: =IF(OR(B29<DATE(2024,10,1),B29>DATE(2024,12,31)),"ERROR","OK") -> OK | AQ29: =IF(OR(S29="Delivered",S29="Cancelled",S29="RTO",S29="In Transit"),"OK","ERROR") -> OK
A30: UT-100029 | B30: 45572 | C30: CUST_10028 | D30: New | E30: TOP-DNM-M | F30: Tops | G30: Denim Shirt | H30: 1899 | I30: 1 | J30: 1899 | L30: 0 | M30: COD | N30: Mobile App | O30: Rajkot | P30: Gujarat | Q30: Mumbai | S30: RTO | T30: No | W30: Not Applicable | AB30: =COUNTIF(A$2:A$347,A30) -> 1 | AC30: =LEN(S30)-LEN(TRIM(S30)) -> 0 | AD30: =LEN(E30)-LEN(SUBSTITUTE(E30,"-","")) -> 2 | AE30: =IF(I30>10,"FLAG","OK") -> OK | AF30: =IF(OR(H30<=0,H30>10000),"FLAG","OK") -> OK | AG30: =IF(OR(L30<0,L30>100),"FLAG","OK") -> OK | AI30: =IF(AG30=J30,"OK","ERROR") -> ERROR | AJ30: =IF(R30<B30,"ERROR","OK") -> ERROR | AK30: =IF(AND(S30="Cancelled",R30<>""),"ERROR","OK") -> OK | AL30: =IF(AND(T30="Yes",U30=""),"ERROR","OK") -> OK | AM30: =IF(V30<R30,"ERROR","OK") -> OK | AN30: =IF(AND(I30>0,MOD(I30,1)=0),"OK","ERROR") -> OK | AO30: =IF(OR(B30="",B30<DATE(2024,10,1),B30>DATE(2024,12,31)),"ERROR","OK") -> OK | AP30: =IF(OR(B30<DATE(2024,10,1),B30>DATE(2024,12,31)),"ERROR","OK") -> OK | AQ30: =IF(OR(S30="Delivered",S30="Cancelled",S30="RTO",S30="In Transit"),"OK","ERROR") -> OK
A31: UT-100030 | B31: 45572 | C31: CUST_10029 | D31: New | E31: BOT-CRG-L | F31: Bottoms | G31: Cargo Pants | H31: 2199 | I31: 1 | J31: 2199 | K31: DIWALI20 | L31: 20 | M31: Credit Card | N31: Website | O31: Kanpur | P31: Uttar Pradesh | Q31: Delhi | R31: 45585 | S31: Delivered | T31: No | W31: Not Applicable | AB31: =COUNTIF(A$2:A$347,A31) -> 1 | AC31: =LEN(S31)-LEN(TRIM(S31)) -> 0 | AD31: =LEN(E31)-LEN(SUBSTITUTE(E31,"-","")) -> 2 | AE31: =IF(I31>10,"FLAG","OK") -> OK | AF31: =IF(OR(H31<=0,H31>10000),"FLAG","OK") -> OK | AG31: =IF(OR(L31<0,L31>100),"FLAG","OK") -> OK | AI31: =IF(AG31=J31,"OK","ERROR") -> ERROR | AJ31: =IF(R31<B31,"ERROR","OK") -> OK | AK31: =IF(AND(S31="Cancelled",R31<>""),"ERROR","OK") -> OK | AL31: =IF(AND(T31="Yes",U31=""),"ERROR","OK") -> OK | AM31: =IF(V31<R31,"ERROR","OK") -> ERROR | AN31: =IF(AND(I31>0,MOD(I31,1)=0),"OK","ERROR") -> OK | AO31: =IF(OR(B31="",B31<DATE(2024,10,1),B31>DATE(2024,12,31)),"ERROR","OK") -> OK | AP31: =IF(OR(B31<DATE(2024,10,1),B31>DATE(2024,12,31)),"ERROR","OK") -> OK | AQ31: =IF(OR(S31="Delivered",S31="Cancelled",S31="RTO",S31="In Transit"),"OK","ERROR") -> OK
A32: UT-100031 | B32: 45572 | C32: CUST_10030 | D32: Returning | E32: DRS-EVE-S | F32: Dresses | G32: Evening Gown | H32: 5499 | I32: 1 | J32: 5499 | L32: 0 | M32: Credit Card | N32: Mobile App | O32: Mumbai | P32: Maharashtra | Q32: Mumbai | R32: 45586 | S32: Delivered | T32: Yes | U32: Size Issue | V32: 45606 | W32: Processed | AB32: =COUNTIF(A$2:A$347,A32) -> 1 | AC32: =LEN(S32)-LEN(TRIM(S32)) -> 0 | AD32: =LEN(E32)-LEN(SUBSTITUTE(E32,"-","")) -> 2 | AE32: =IF(I32>10,"FLAG","OK") -> OK | AF32: =IF(OR(H32<=0,H32>10000),"FLAG","OK") -> OK | AG32: =IF(OR(L32<0,L32>100),"FLAG","OK") -> OK | AI32: =IF(AG32=J32,"OK","ERROR") -> ERROR | AJ32: =IF(R32<B32,"ERROR","OK") -> OK | AK32: =IF(AND(S32="Cancelled",R32<>""),"ERROR","OK") -> OK | AL32: =IF(AND(T32="Yes",U32=""),"ERROR","OK") -> OK | AM32: =IF(V32<R32,"ERROR","OK") -> OK | AN32: =IF(AND(I32>0,MOD(I32,1)=0),"OK","ERROR") -> OK | AO32: =IF(OR(B32="",B32<DATE(2024,10,1),B32>DATE(2024,12,31)),"ERROR","OK") -> OK | AP32: =IF(OR(B32<DATE(2024,10,1),B32>DATE(2024,12,31)),"ERROR","OK") -> OK | AQ32: =IF(OR(S32="Delivered",S32="Cancelled",S32="RTO",S32="In Transit"),"OK","ERROR") -> OK
A33: UT-100032 | B33: 45573 | C33: CUST_10031 | D33: New | E33: TOP-BAS-M | F33: Tops | G33: Basic Tank | H33: 899 | I33: 2 | J33: 1798 | L33: 0 | M33: UPI | N33: Website | O33: Delhi | P33: Delhi | Q33: Delhi | R33: 45579 | S33: Delivered | T33: No | W33: Not Applicable | AB33: =COUNTIF(A$2:A$347,A33) -> 1 | AC33: =LEN(S33)-LEN(TRIM(S33)) -> 0 | AD33: =LEN(E33)-LEN(SUBSTITUTE(E33,"-","")) -> 2 | AE33: =IF(I33>10,"FLAG","OK") -> OK | AF33: =IF(OR(H33<=0,H33>10000),"FLAG","OK") -> OK | AG33: =IF(OR(L33<0,L33>100),"FLAG","OK") -> OK | AI33: =IF(AG33=J33,"OK","ERROR") -> ERROR | AJ33: =IF(R33<B33,"ERROR","OK") -> OK | AK33: =IF(AND(S33="Cancelled",R33<>""),"ERROR","OK") -> OK | AL33: =IF(AND(T33="Yes",U33=""),"ERROR","OK") -> OK | AM33: =IF(V33<R33,"ERROR","OK") -> ERROR | AN33: =IF(AND(I33>0,MOD(I33,1)=0),"OK","ERROR") -> OK | AO33: =IF(OR(B33="",B33<DATE(2024,10,1),B33>DATE(2024,12,31)),"ERROR","OK") -> OK | AP33: =IF(OR(B33<DATE(2024,10,1),B33>DATE(2024,12,31)),"ERROR","OK") -> OK | AQ33: =IF(OR(S33="Delivered",S33="Cancelled",S33="RTO",S33="In Transit"),"OK","ERROR") -> OK
A34: UT-100033 | B34: 45573 | C34: CUST_10032 | D34: New | E34: OUT-WOL-L | F34: Outerwear | G34: Wool Coat | H34: 6999 | I34: 1 | J34: 6999 | K34: FIRST15 | L34: 15 | M34: Debit Card | N34: Instagram Shop | O34: Kolkata | P34: West Bengal | Q34: Delhi | R34: 45581 | S34: Delivered | T34: Yes | U34: Quality Defect | V34: 45601 | W34: Processed | AB34: =COUNTIF(A$2:A$347,A34) -> 1 | AC34: =LEN(S34)-LEN(TRIM(S34)) -> 0 | AD34: =LEN(E34)-LEN(SUBSTITUTE(E34,"-","")) -> 2 | AE34: =IF(I34>10,"FLAG","OK") -> OK | AF34: =IF(OR(H34<=0,H34>10000),"FLAG","OK") -> OK | AG34: =IF(OR(L34<0,L34>100),"FLAG","OK") -> OK | AI34: =IF(AG34=J34,"OK","ERROR") -> ERROR | AJ34: =IF(R34<B34,"ERROR","OK") -> OK | AK34: =IF(AND(S34="Cancelled",R34<>""),"ERROR","OK") -> OK | AL34: =IF(AND(T34="Yes",U34=""),"ERROR","OK") -> OK | AM34: =IF(V34<R34,"ERROR","OK") -> OK | AN34: =IF(AND(I34>0,MOD(I34,1)=0),"OK","ERROR") -> OK | AO34: =IF(OR(B34="",B34<DATE(2024,10,1),B34>DATE(2024,12,31)),"ERROR","OK") -> OK | AP34: =IF(OR(B34<DATE(2024,10,1),B34>DATE(2024,12,31)),"ERROR","OK") -> OK | AQ34: =IF(OR(S34="Delivered",S34="Cancelled",S34="RTO",S34="In Transit"),"OK","ERROR") -> OK
A35: UT-100034 | B35: 45573 | C35: CUST_10033 | D35: Returning | E35: ACC-WCH-OS | F35: Accessories | G35: Fashion Watch | H35: 2999 | I35: 1 | J35: 2999 | L35: 0 | M35: Credit Card | N35: Mobile App | O35: Chennai | P35: Tamil Nadu | Q35: Bangalore | R35: 45580 | S35: Delivered | T35: No | W35: Not Applicable | AB35: =COUNTIF(A$2:A$347,A35) -> 1 | AC35: =LEN(S35)-LEN(TRIM(S35)) -> 0 | AD35: =LEN(E35)-LEN(SUBSTITUTE(E35,"-","")) -> 2 | AE35: =IF(I35>10,"FLAG","OK") -> OK | AF35: =IF(OR(H35<=0,H35>10000),"FLAG","OK") -> OK | AG35: =IF(OR(L35<0,L35>100),"FLAG","OK") -> OK | AI35: =IF(AG35=J35,"OK","ERROR") -> ERROR | AJ35: =IF(R35<B35,"ERROR","OK") -> OK | AK35: =IF(AND(S35="Cancelled",R35<>""),"ERROR","OK") -> OK | AL35: =IF(AND(T35="Yes",U35=""),"ERROR","OK") -> OK | AM35: =IF(V35<R35,"ERROR","OK") -> ERROR | AN35: =IF(AND(I35>0,MOD(I35,1)=0),"OK","ERROR") -> OK | AO35: =IF(OR(B35="",B35<DATE(2024,10,1),B35>DATE(2024,12,31)),"ERROR","OK") -> OK | AP35: =IF(OR(B35<DATE(2024,10,1),B35>DATE(2024,12,31)),"ERROR","OK") -> OK | AQ35: =IF(OR(S35="Delivered",S35="Cancelled",S35="RTO",S35="In Transit"),"OK","ERROR") -> OK
A36: UT-100035 | B36: 45573 | C36: CUST_10034 | D36: New | E36: BOT-DNM-S | F36: Bottoms | G36: Denim Shorts | H36: 1599 | I36: 1 | J36: 1599 | L36: 0 | M36: COD | N36: Website | O36: Hyderabad | P36: Telangana | Q36: Bangalore | R36: 45582 | S36: Delivered | T36: Yes | U36: Size Issue | V36: 45604 | W36: Processed | AB36: =COUNTIF(A$2:A$347,A36) -> 1 | AC36: =LEN(S36)-LEN(TRIM(S36)) -> 0 | AD36: =LEN(E36)-LEN(SUBSTITUTE(E36,"-","")) -> 2 | AE36: =IF(I36>10,"FLAG","OK") -> OK | AF36: =IF(OR(H36<=0,H36>10000),"FLAG","OK") -> OK | AG36: =IF(OR(L36<0,L36>100),"FLAG","OK") -> OK | AI36: =IF(AG36=J36,"OK","ERROR") -> ERROR | AJ36: =IF(R36<B36,"ERROR","OK") -> OK | AK36: =IF(AND(S36="Cancelled",R36<>""),"ERROR","OK") -> OK | AL36: =IF(AND(T36="Yes",U36=""),"ERROR","OK") -> OK | AM36: =IF(V36<R36,"ERROR","OK") -> OK | AN36: =IF(AND(I36>0,MOD(I36,1)=0),"OK","ERROR") -> OK | AO36: =IF(OR(B36="",B36<DATE(2024,10,1),B36>DATE(2024,12,31)),"ERROR","OK") -> OK | AP36: =IF(OR(B36<DATE(2024,10,1),B36>DATE(2024,12,31)),"ERROR","OK") -> OK | AQ36: =IF(OR(S36="Delivered",S36="Cancelled",S36="RTO",S36="In Transit"),"OK","ERROR") -> OK
A37: UT-100036 | B37: 45574 | C37: CUST_10035 | D37: New | E37: DRS-SUN-M | F37: Dresses | G37: Sundress | H37: 1999 | I37: 1 | J37: 1999 | K37: DIWALI20 | L37: 20 | M37: Wallet | N37: Mobile App | O37: Pune | P37: Maharashtra | Q37: Mumbai | R37: 45581 | S37: Delivered | T37: No | W37: Not Applicable | AB37: =COUNTIF(A$2:A$347,A37) -> 1 | AC37: =LEN(S37)-LEN(TRIM(S37)) -> 0 | AD37: =LEN(E37)-LEN(SUBSTITUTE(E37,"-","")) -> 2 | AE37: =IF(I37>10,"FLAG","OK") -> OK | AF37: =IF(OR(H37<=0,H37>10000),"FLAG","OK") -> OK | AG37: =IF(OR(L37<0,L37>100),"FLAG","OK") -> OK | AI37: =IF(AG37=J37,"OK","ERROR") -> ERROR | AJ37: =IF(R37<B37,"ERROR","OK") -> OK | AK37: =IF(AND(S37="Cancelled",R37<>""),"ERROR","OK") -> OK | AL37: =IF(AND(T37="Yes",U37=""),"ERROR","OK") -> OK | AM37: =IF(V37<R37,"ERROR","OK") -> ERROR | AN37: =IF(AND(I37>0,MOD(I37,1)=0),"OK","ERROR") -> OK | AO37: =IF(OR(B37="",B37<DATE(2024,10,1),B37>DATE(2024,12,31)),"ERROR","OK") -> OK | AP37: =IF(OR(B37<DATE(2024,10,1),B37>DATE(2024,12,31)),"ERROR","OK") -> OK | AQ37: =IF(OR(S37="Delivered",S37="Cancelled",S37="RTO",S37="In Transit"),"OK","ERROR") -> OK
A38: UT-100037 | B38: 45574 | C38: CUST_10036 | D38: New | E38: TOP-RFL-S | F38: Tops | G38: Ruffle Top | H38: 1799 | I38: 1 | J38: 1799 | L38: 0 | M38: UPI | N38: Instagram Shop | O38: Ahmedabad | P38: Gujarat | Q38: Mumbai | R38: 45582 | S38: Delivered | T38: Yes | U38: Changed Mind | V38: 45608 | W38: Processed | AB38: =COUNTIF(A$2:A$347,A38) -> 1 | AC38: =LEN(S38)-LEN(TRIM(S38)) -> 0 | AD38: =LEN(E38)-LEN(SUBSTITUTE(E38,"-","")) -> 2 | AE38: =IF(I38>10,"FLAG","OK") -> OK | AF38: =IF(OR(H38<=0,H38>10000),"FLAG","OK") -> OK | AG38: =IF(OR(L38<0,L38>100),"FLAG","OK") -> OK | AI38: =IF(AG38=J38,"OK","ERROR") -> ERROR | AJ38: =IF(R38<B38,"ERROR","OK") -> OK | AK38: =IF(AND(S38="Cancelled",R38<>""),"ERROR","OK") -> OK | AL38: =IF(AND(T38="Yes",U38=""),"ERROR","OK") -> OK | AM38: =IF(V38<R38,"ERROR","OK") -> OK | AN38: =IF(AND(I38>0,MOD(I38,1)=0),"OK","ERROR") -> OK | AO38: =IF(OR(B38="",B38<DATE(2024,10,1),B38>DATE(2024,12,31)),"ERROR","OK") -> OK | AP38: =IF(OR(B38<DATE(2024,10,1),B38>DATE(2024,12,31)),"ERROR","OK") -> OK | AQ38: =IF(OR(S38="Delivered",S38="Cancelled",S38="RTO",S38="In Transit"),"OK","ERROR") -> OK
A39: UT-100038 | B39: 45574 | C39: CUST_10037 | D39: Returning | E39: OUT-LTH-M | F39: Outerwear | G39: Leather Jacket | H39: 7999 | I39: 1 | J39: 7999 | L39: 0 | M39: Credit Card | N39: Website | O39: Jaipur | P39: Rajasthan | Q39: Delhi | R39: 45583 | S39: Delivered | T39: No | W39: Not Applicable | AB39: =COUNTIF(A$2:A$347,A39) -> 1 | AC39: =LEN(S39)-LEN(TRIM(S39)) -> 0 | AD39: =LEN(E39)-LEN(SUBSTITUTE(E39,"-","")) -> 2 | AE39: =IF(I39>10,"FLAG","OK") -> OK | AF39: =IF(OR(H39<=0,H39>10000),"FLAG","OK") -> OK | AG39: =IF(OR(L39<0,L39>100),"FLAG","OK") -> OK | AI39: =IF(AG39=J39,"OK","ERROR") -> ERROR | AJ39: =IF(R39<B39,"ERROR","OK") -> OK | AK39: =IF(AND(S39="Cancelled",R39<>""),"ERROR","OK") -> OK | AL39: =IF(AND(T39="Yes",U39=""),"ERROR","OK") -> OK | AM39: =IF(V39<R39,"ERROR","OK") -> ERROR | AN39: =IF(AND(I39>0,MOD(I39,1)=0),"OK","ERROR") -> OK | AO39: =IF(OR(B39="",B39<DATE(2024,10,1),B39>DATE(2024,12,31)),"ERROR","OK") -> OK | AP39: =IF(OR(B39<DATE(2024,10,1),B39>DATE(2024,12,31)),"ERROR","OK") -> OK | AQ39: =IF(OR(S39="Delivered",S39="Cancelled",S39="RTO",S39="In Transit"),"OK","ERROR") -> OK
A40: UT-100039 | B40: 45574 | C40: CUST_10038 | D40: New | E40: ACC-SNG-OS | F40: Accessories | G40: Sunglasses | H40: 1499 | I40: 1 | J40: 1499 | K40: FLAT10 | L40: 10 | M40: Debit Card | N40: Mobile App | O40: Lucknow | P40: Uttar Pradesh | Q40: Delhi | R40: 45582 | S40: Delivered | T40: No | W40: Not Applicable | AB40: =COUNTIF(A$2:A$347,A40) -> 1 | AC40: =LEN(S40)-LEN(TRIM(S40)) -> 0 | AD40: =LEN(E40)-LEN(SUBSTITUTE(E40,"-","")) -> 2 | AE40: =IF(I40>10,"FLAG","OK") -> OK | AF40: =IF(OR(H40<=0,H40>10000),"FLAG","OK") -> OK | AG40: =IF(OR(L40<0,L40>100),"FLAG","OK") -> OK | AI40: =IF(AG40=J40,"OK","ERROR") -> ERROR | AJ40: =IF(R40<B40,"ERROR","OK") -> OK | AK40: =IF(AND(S40="Cancelled",R40<>""),"ERROR","OK") -> OK | AL40: =IF(AND(T40="Yes",U40=""),"ERROR","OK") -> OK | AM40: =IF(V40<R40,"ERROR","OK") -> ERROR | AN40: =IF(AND(I40>0,MOD(I40,1)=0),"OK","ERROR") -> OK | AO40: =IF(OR(B40="",B40<DATE(2024,10,1),B40>DATE(2024,12,31)),"ERROR","OK") -> OK | AP40: =IF(OR(B40<DATE(2024,10,1),B40>DATE(2024,12,31)),"ERROR","OK") -> OK | AQ40: =IF(OR(S40="Delivered",S40="Cancelled",S40="RTO",S40="In Transit"),"OK","ERROR") -> OK
...

Sheet Cleaning_Log
A1: Issue_ID | B1: Column_Name | C1: Issue_Type | D1: Problem_Details | E1: Action_Taken | F1: Formula_Used
A2: CL01 | B2: Reason | C2: Missing Value | D2: 166 blanks where Return?=No | E2: Ignore (Excepted business case) | F2: COUNTBLANK(U2:U347)
A3: CL02 | B3: Del Data | C3: Missing Value | D3: 18 blanks for Cancelled/ RTO/In-Transit | E3: Allowed | F3: COUNTBLANK(R2:R347)
A4: CL03 | B4: Discount Code | C4: Missing Value | D4: 206 orders without promo | E4: Treated as 0 discount | F4: COUNTBLANK(K2:K347)
A5: CL04 | B5: Ret Rec | C5: Missing Value | D5: 166 blanks for non-returned orders | E5: Ignored | F5: COUNTBLANK(V2:V347)
A6: CL05 | B6: Order ID | C6: Duplicate Check | D6: No duplicate order_id found in dataset | E6: No action required | F6: COUNTIF(A2:A347,A2)
A7: CL06 | B7: Delivery Date | C7: Format Check | D7: Dates stored correctly as Excel date values | E7: No action required | F7: Checked via Number Format
A8: CL07 | B8: Status | C8: Format Check | D8: No extra spaces found(LEN/TRIM = 0 for all rows | E8: No action required | F8: LEN(S2)-LEN(TRIM(S2)
A9: CL08 | B9: SKU | C9: Format Check | D9: All values follow CAT-STYLE-SIZE pattern | E9: No action required | F9: LEN(E2)-LEN(SUBSTITUTE(E2,"-'"")
A10: CL09 | B10: Quantity | C10: Outlier Check | D10: No unusually high quantities found(>10) | E10: No action required | F10: IF(I2>10,"FLAG","OK")
A11: CL10 | B11: Unit Price | C11: Outlier Check | D11: No zero/negative or extreme prices found | E11: No action required | F11: IF(OR(H2<=0,H2>10000),"FLAG","OK")
A12: CL11 | B12: Discount % | C12: Outlier Check | D12: All values within 0–100 | E12: No action required | F12: IF(OR(L2<0,L2>100),"FLAG","OK")
... A15: CL14 | B15: Quantity | C15: Validation | D15: Row 11 has quantity = -1 (invalid) | E15: Flagged; excluded from quantity KPIs | F15: IF(AND(I2>0,MOD(I2,1)=0),"OK","ERROR")
A16: CL15 | B16: Order Date | C16: Validation | D16: UT-100003 has order_date = 10-01-2024 (outside Q4) | E16: Excluded from Q4 metrics

Sheet Validation
A1: Rule_ID | B1: Validation_Rule | C1: Formula | D1: Status | E1: Error_Count
A2: V1 | B2: order_id format UT-100001 | C2: =COUNTIF(Raw_Data!A2:A347,"UT-??????") -> 346 | D2: =IF(E2=0,"PASS","FAIL") -> PASS | E2: =COUNTA(Raw_Data!A2:A347)-C2 -> 0
A3: V2 | B3: customer_type only New or Returning | C3: =COUNTIF(Raw_Data!D2:D347,"New")+COUNTIF(Raw_Data!D2:D347,"Returning") -> 346 | D3: =IF(E3=0,"PASS","FAIL") -> PASS | E3: =COUNTA(Raw_Data!D2:D347)-C3 -> 0
A4: V3 | B4: quantity positive integer | C4: {=SUMPRODUCT(--(Raw_Data!I2:I347>0),--(MOD(Raw_Data!I2:I347,1)=0))} -> 345 | D4: =IF(E4=0,"PASS","FAIL") -> FAIL | E4: =COUNTA(Raw_Data!I2:I347)-C4 -> 1
A5: V4 | B5: discount_percent between 0 and 100 | C5: =COUNTIFS(Raw_Data!L2:L347,">=0",Raw_Data!L2:L347,"<=100") -> 346 | D5: =IF(E5=0,"PASS","FAIL") -> PASS | E5: =COUNTA(Raw_Data!L2:L347)-C5 -> 0
A6: V5 | B6: order_date within Q4 2024 | C6: =COUNTIFS(Raw_Data!B2:B347,">="&DATE(2024,10,1),Raw_Data!B2:B347,"<="&DATE(2024,12,31)) -> 345 | D6: =IF(E6=0,"PASS","FAIL") -> FAIL | E6: =COUNTA(Raw_Data!B2:B347)-C6 -> 1
A7: V6 | B7: payment_method allowed values | C7: =COUNTIF(Raw_Data!M2:M347,"UPI") +COUNTIF(Raw_Data!M2:M347,"Credit Card") +COUNTIF(Raw_Data!M2:M347,"Debit Card") +COUNTIF(Raw_Data!M2:M347,"Wallet") +COUNTIF(Raw_Data!M2:M347,"COD") -> 346 | D7: =IF(E7=0,"PASS","FAIL") -> PASS | E7: =COUNTA(Raw_Data!M2:M347)-C7 -> 0
A8: V7 | B8: delivery_status allowed values | C8: {=SUMPRODUCT(--(TRIM(Raw_Data!S2:S347)="Delivered") +--(TRIM(Raw_Data!S2:S347)="Cancelled") +--(TRIM(Raw_Data!S2:S347)="RTO") +--(TRIM(Raw_Data!S2:S347)="In Transit"))} -> 345 | D8: =IF(E8=0,"PASS","FAIL") -> PASS | E8: =COUNTA(Raw_Data!S2:S347)-C7 -> 0
A9: V8 | B9: return_initiated No → return_reason blank | C9: {=SUMPRODUCT(--(Raw_Data!T2:T347="No"),--(Raw_Data!U2:U347<>""))} -> 0 | D9: =IF(E9=0,"PASS","FAIL") -> PASS | E9: =C9 -> 0
A10: V9 | B10: warehouse_origin allowed values Mumbai/Delhi/Bangalore | C10: =COUNTIF(Raw_Data!Q2:Q347,"Mumbai") +COUNTIF(Raw_Data!Q2:Q347,"Delhi") +COUNTIF(Raw_Data!Q2:Q347,"Bangalore") -> 346 | D10: =IF(E10=0,"PASS","FAIL") -> PASS | E10: =COUNTA(Raw_Data!Q2:Q347)-C10 -> 0
A11: V10 | B11: refund_status must be Not Applicable when return_initiated = No | C11: {=SUMPRODUCT(--(Raw_Data!T2:T347="No"),--(Raw_Data!W2:W347<>"Not Applicable"))} -> 0 | D11: =IF(E11=0,"PASS","FAIL") -> PASS | E11: =C11 -> 0

Sheet Weekly_Combo_Data
A3: Row Labels | B3: Count of Order ID
A4: 10-01-2024 - 16-01-2024 | B4: 1
A5: 45301 | B5: 1
A6: 25-09-2024 - 01-10-2024 | B6: 4
A7: 45566 | B7: 4
A8: 02-10-2024 - 08-10-2024 | B8: 30
A9: 45567 | B9: 5
A10: 45568 | B10: 5
A11: 45569 | B11: 4
A12: 45570 | B12: 4
A13: 45571 | B13: 4
A14: 45572 | B14: 4
A15: 45573 | B15: 4
A16: 09-10-2024 - 15-10-2024 | B16: 29
A17: 45574 | B17: 4
A18: 45575 | B18: 5
A19: 45576 | B19: 4
A20: 45577 | B20: 4
A21: 45578 | B21: 4
A22: 45579 | B22: 4
A23: 45580 | B23: 4
A24: 16-10-2024 - 22-10-2024 | B24: 28
A25: 45581 | B25: 4
A26: 45582 | B26: 4
A27: 45583 | B27: 4
A28: 45584 | B28: 4
A29: 45585 | B29: 4
A30: 45586 | B30: 4
A31: 45587 | B31: 4
A32: 23-10-2024 - 29-10-2024 | B32: 30
A33: 45588 | B33: 4
A34: 45589 | B34: 4
A35: 45590 | B35: 4
A36: 45591 | B36: 4
A37: 45592 | B37: 3
A38: 45593 | B38: 5
A39: 45594 | B39: 6
A40: 30-10-2024 - 05-11-2024 | B40: 29
A41: 45595 | B41: 5
A42: 45596 | B42: 5
...

Sheet Customer_Analysis
A1: Return? | B1: Yes
A3: Row Labels | B3: Count of Order ID
A4: New | B4: 147
A5: Returning | B5: 33
A6: Grand Total | B6: 180
A8: Return? | B8: (All)
A10: Row Labels | B10: Count of Order ID
A11: New | B11: 270
A12: Returning | B12: 76
A13: Grand Total | B13: 346
A15: Type | B15: Total Orders | C15: Returned Orders | D15: Return Rate
A16: New | B16: 270 | C16: 147 | D16: =C16/B16 -> 0.54444444
A17: Returning | B17: 76 | C17: 33 | D17: =C17/B17 -> 0.43421053
B18: =SUM(B16:B17) -> 346 | C18: =SUM(C16:C17) -> 180

Sheet Category_Analysis
A1: Return? | B1: Yes
A3: Row Labels | B3: Returned Orders | C3: Returned Revenue
A4: Accessories | B4: 16 | C4: 25973
A5: Bottoms | B5: 25 | C5: 63671
A6: Dresses | B6: 44 | C6: 177356
A7: Outerwear | B7: 52 | C7: 282448
A8: Tops | B8: 43 | C8: 98448
A9: Grand Total | B9: 180 | C9: 647896

Sheet Viz_1_Weekly_Returns
A1: Return? | B1: Yes | D1: Return? | E1: (All)
A3: Row Labels | B3: Weekly Returns | D3: Row Labels | E3: Weekly Orders | F3: Return Rate
A4: 30-10-2024 - 05-11-2024 | B4: 20 | D4: 30-10-2024 - 05-11-2024 | E4: 29 | F4: =B4/E4 -> 0.68965517
A5: 27-11-2024 - 03-12-2024 | B5: 12 | D5: 27-11-2024 - 03-12-2024 | E5: 24 | F5: =B5/E5 -> 0.5
A6: 25-12-2024 - 31-12-2024 | B6: 15 | D6: 25-12-2024 - 31-12-2024 | E6: 25 | F6: =B6/E6 -> 0.6
A7: 25-09-2024 - 01-10-2024 | B7: 2 | D7: 25-09-2024 - 01-10-2024 | E7: 4 | F7: =B7/E7 -> 0.5
A8: 23-10-2024 - 29-10-2024 | B8: 17 | D8: 23-10-2024 - 29-10-2024 | E8: 30 | F8: =B8/E8 -> 0.56666667
A9: 20-11-2024 - 26-11-2024 | B9: 12 | D9: 20-11-2024 - 26-11-2024 | E9: 21 | F9: =B9/E9 -> 0.57142857
A10: 18-12-2024 - 24-12-2024 | B10: 17 | D10: 18-12-2024 - 24-12-2024 | E10: 28 | F10: =B10/E10 -> 0.60714286
A11: 16-10-2024 - 22-10-2024 | B11: 11 | D11: 16-10-2024 - 22-10-2024 | E11: 28 | F11: =B11/E11 -> 0.39285714
A12: 13-11-2024 - 19-11-2024 | B12: 11 | D12: 13-11-2024 - 19-11-2024 | E12: 21 | F12: =B12/E12 -> 0.52380952
A13: 11-12-2024 - 17-12-2024 | B13: 16 | D13: 11-12-2024 - 17-12-2024 | E13: 28 | F13: =B13/E13 -> 0.57142857
A14: 09-10-2024 - 15-10-2024 | B14: 12 | D14: 10-01-2024 - 16-01-2024 | E14: 1 | F14: 0
A15: 06-11-2024 - 12-11-2024 | B15: 10 | D15: 09-10-2024 - 15-10-2024 | E15: 29 | F15: =B14/E15 -> 0.4137931
A16: 04-12-2024 - 10-12-2024 | B16: 13 | D16: 06-11-2024 - 12-11-2024 | E16: 20 | F16: =B15/E15 -> 0.34482759
A17: 02-10-2024 - 08-10-2024 | B17: 12 | D17: 04-12-2024 - 10-12-2024 | E17: 28 | F17: =B16/E16 -> 0.65
A18: Grand Total | B18: 180 | D18: 02-10-2024 - 08-10-2024 | E18: 30 | F18: =B17/E17 -> 0.42857143
D19: Grand Total | E19: 346
B21: Week | C21: Weekly Orders | D21: Weekly Returns | E21: Return Rate
B22: 30-10-2024 - 05-11-2024 | C22: 29 | D22: 20 | E22: =D22/C22 -> 0.68965517
B23: 27-11-2024 - 03-12-2024 | C23: 24 | D23: 12 | E23: =D23/C23 -> 0.5
B24: 25-12-2024 - 31-12-2024 | C24: 25 | D24: 15 | E24: =D24/C24 -> 0.6
B25: 25-09-2024 - 01-10-2024 | C25: 4 | D25: 2 | E25: =D25/C25 -> 0.5
B26: 23-10-2024 - 29-10-2024 | C26: 30 | D26: 17 | E26: =D26/C26 -> 0.56666667
B27: 20-11-2024 - 26-11-2024 | C27: 21 | D27: 12 | E27: =D27/C27 -> 0.57142857
B28: 18-12-2024 - 24-12-2024 | C28: 28 | D28: 17 | E28: =D28/C28 -> 0.60714286
B29: 16-10-2024 - 22-10-2024 | C29: 28 | D29: 11 | E29: =D29/C29 -> 0.39285714
B30: 13-11-2024 - 19-11-2024 | C30: 21 | D30: 11 | E30: =D30/C30 -> 0.52380952
B31: 11-12-2024 - 17-12-2024 | C31: 28 | D31: 16 | E31: =D31/C31 -> 0.57142857
B32: 10-01-2024 - 16-01-2024 | C32: 1 | D32: 1 | E32: =D32/C32 -> 1
B33: 09-10-2024 - 15-10-2024 | C33: 29 | D33: 12 | E33: =D33/C33 -> 0.4137931
... B36: 02-10-2024 - 08-10-2024 | C36: 30 | D36: 12 | E36: =D36/C36 -> 0.4

Sheet Viz_2_Category
A1: Return? | B1: Yes | D1: Return? | E1: (All)
A3: Row Labels | B3: Returned Orders | D3: Row Labels | E3: Total Orders
A4: Accessories | B4: 16 | D4: Accessories | E4: 68
A5: Bottoms | B5: 25 | D5: Bottoms | E5: 67
A6: Dresses | B6: 44 | D6: Dresses | E6: 70
A7: Outerwear | B7: 52 | D7: Outerwear | E7: 68
A8: Tops | B8: 43 | D8: Tops | E8: 73
A9: Grand Total | B9: 180 | D9: Grand Total | E9: 346
A11: Row Labels | B11: Return Rate | C11: Returned Orders | D11: Total Orders
A12: Accessories | B12: =C12/D12 -> 0.23529412 | C12: 16 | D12: 68
A13: Bottoms | B13: =C13/D13 -> 0.37313433 | C13: 25 | D13: 67
A14: Dresses | B14: =C14/D14 -> 0.62857143 | C14: 44 | D14: 70
A15: Outerwear | B15: =C15/D15 -> 0.76470588 | C15: 52 | D15: 68
A16: Tops | B16: =C16/D16 -> 0.5890411 | C16: 43 | D16: 73

Sheet Viz_3_Return_Reasons
A1: Return? | B1: Yes
A3: Row Labels | B3: Return count
A4: Changed Mind | B4: 29
A5: Damaged in Transit | B5: 24
A6: Quality Defect | B6: 32
A7: Size Issue | B7: 67
A8: Wrong Item | B8: 28
A9: Grand Total | B9: 180

Sheet Viz_4_Customer_Source
A1: Return? | B1: Yes
A3: Count of Order ID | B3: Column Labels
A4: Row Labels | B4: Instagram Shop | C4: Mobile App | D4: Website | E4: Grand Total
A5: New | B5: 63 | C5: 46 | D5: 38 | E5: 147
A6: Returning | B6: 8 | C6: 15 | D6: 10 | E6: 33
A7: Grand Total | B7: 71 | C7: 61 | D7: 48 | E7: 180
A11: Return? | B11: (All)
A13: Count of Order ID | B13: Column Labels
A14: Row Labels | B14: Instagram Shop | C14: Mobile App | D14: Website | E14: Grand Total
A15: New | B15: 88 | C15: 89 | D15: 93 | E15: 270
A16: Returning | B16: 21 | C16: 27 | D16: 28 | E16: 76
A17: Grand Total | B17: 109 | C17: 116 | D17: 121 | E17: 346
A20: Customer Type | B20: Channel | C20: Return Rate | D20: Returned Orders | E20: Total Orders
A21: New | B21: Instagram Shop | C21: 0.7159 | D21: 63 | E21: 88
A22: New | B22: Mobile App | C22: 0.5169 | D22: 46 | E22: 89
A23: New | B23: Website | C23: 0.4086 | D23: 38 | E23: 93
A24: Returning | B24: Instagram Shop | C24: 0.381 | D24: 8 | E24: 21
A25: Returning | B25: Mobile App | C25: 0.5556 | D25: 15 | E25: 27
A26: Returning | B26: Website | C26: 0.3571 | D26: 10 | E26: 28

Sheet Viz_5_Payment
A1: Payment Mode | B1: Return Rate | C1: Total Orders | D1: Returned Orders
A2: COD | B2: =D2/C2 -> 0.6031746 | C2: =COUNTIFS(Raw_Data!M:M,"COD") -> 63 | D2: =COUNTIFS(Raw_Data!M:M,"COD",Raw_Data!T:T,"Yes") -> 38
A3: Prepaid | B3: =D3/C3 -> 0.5 | C3: =COUNTIFS(Raw_Data!M:M,"<>COD",Raw_Data!M:M,"<>") -> 284 | D3: =COUNTIFS(Raw_Data!M:M,"<>COD",Raw_Data!T:T,"Yes") -> 142

Sheet KPI_Summary
A1: Metric | B1: Value
A2: Total Orders | B2: =COUNTA(Raw_Data!A2:A347) -> 346
A3: Total Revenue(after Discount) | B3: =SUM(Raw_Data!J2:J347) -> 1023789
A4: Total Units Sold | B4: =SUM(Raw_Data!I2:I347) -> 409
A5: Avarage Order Value | B5: =AVERAGE(Raw_Data!J2:J347) -> 2958.9277
A6: Overall Return Rate | B6: =COUNTIF(Raw_Data!T2:T347,"Yes") / COUNTIF(Raw_Data!S2:S347,"Delivered") -> 0.55045872
A9: Month | B9: Orders
A10: =TEXT(Raw_Data!B2,"MMM") -> Oct
A11: =TEXT(Raw_Data!B3,"MMM") -> Oct
A12: =TEXT(Raw_Data!B4,"MMM") -> Jan
A13: =TEXT(Raw_Data!B5,"MMM") -> Oct
A14: =TEXT(Raw_Data!B6,"MMM") -> Oct
A15: =TEXT(Raw_Data!B7,"MMM") -> Oct
A16: =TEXT(Raw_Data!B8,"MMM") -> Oct
A17: =TEXT(Raw_Data!B9,"MMM") -> Oct
A18: =TEXT(Raw_Data!B10,"MMM") -> Oct
A19: =TEXT(Raw_Data!B11,"MMM") -> Oct
A20: =TEXT(Raw_Data!B12,"MMM") -> Oct
A21: =TEXT(Raw_Data!B13,"MMM") -> Oct
... A347: =TEXT(Raw_Data!B339,"MMM") -> Dec
